Traceback (most recent call last):
  File "/usr/share/miniconda/lib/python3.9/site-packages/jupyter_cache/executors/utils.py", line 51, in single_nb_execution
    executenb(
  File "/usr/share/miniconda/lib/python3.9/site-packages/nbclient/client.py", line 1204, in execute
    return NotebookClient(nb=nb, resources=resources, km=km, **kwargs).execute()
  File "/usr/share/miniconda/lib/python3.9/site-packages/nbclient/util.py", line 84, in wrapped
    return just_run(coro(*args, **kwargs))
  File "/usr/share/miniconda/lib/python3.9/site-packages/nbclient/util.py", line 62, in just_run
    return loop.run_until_complete(coro)
  File "/usr/share/miniconda/lib/python3.9/asyncio/base_events.py", line 647, in run_until_complete
    return future.result()
  File "/usr/share/miniconda/lib/python3.9/site-packages/nbclient/client.py", line 663, in async_execute
    await self.async_execute_cell(
  File "/usr/share/miniconda/lib/python3.9/site-packages/nbclient/client.py", line 965, in async_execute_cell
    await self._check_raise_for_error(cell, cell_index, exec_reply)
  File "/usr/share/miniconda/lib/python3.9/site-packages/nbclient/client.py", line 862, in _check_raise_for_error
    raise CellExecutionError.from_cell_and_msg(cell, exec_reply_content)
nbclient.exceptions.CellExecutionError: An error occurred while executing the following cell:
------------------
input_file1 = get_bigdata('jwst_validation_notebooks',
                     'validation_data',
                     'outlier_detection',
                     'outlier_detection_miri_test', 
                     'det_image_seq1_MIRIMAGE_F560Wexp1_cal.fits')
input_file2 = get_bigdata('jwst_validation_notebooks',
                     'validation_data',
                     'outlier_detection',
                     'outlier_detection_miri_test', 
                     'det_image_seq2_MIRIMAGE_F560Wexp1_cal.fits')
input_file3 = get_bigdata('jwst_validation_notebooks',
                     'validation_data',
                     'outlier_detection',
                     'outlier_detection_miri_test', 
                     'det_image_seq3_MIRIMAGE_F560Wexp1_cal.fits')
input_file4 = get_bigdata('jwst_validation_notebooks',
                     'validation_data',
                     'outlier_detection',
                     'outlier_detection_miri_test', 
                     'det_image_seq4_MIRIMAGE_F560Wexp1_cal.fits')
------------------

[0;31m---------------------------------------------------------------------------[0m
[0;31mgaierror[0m                                  Traceback (most recent call last)
File [0;32m/usr/share/miniconda/lib/python3.9/site-packages/urllib3/connection.py:174[0m, in [0;36mHTTPConnection._new_conn[0;34m(self)[0m
[1;32m    173[0m [38;5;28;01mtry[39;00m:
[0;32m--> 174[0m     conn [38;5;241m=[39m [43mconnection[49m[38;5;241;43m.[39;49m[43mcreate_connection[49m[43m([49m
[1;32m    175[0m [43m        [49m[43m([49m[38;5;28;43mself[39;49m[38;5;241;43m.[39;49m[43m_dns_host[49m[43m,[49m[43m [49m[38;5;28;43mself[39;49m[38;5;241;43m.[39;49m[43mport[49m[43m)[49m[43m,[49m[43m [49m[38;5;28;43mself[39;49m[38;5;241;43m.[39;49m[43mtimeout[49m[43m,[49m[43m [49m[38;5;241;43m*[39;49m[38;5;241;43m*[39;49m[43mextra_kw[49m
[1;32m    176[0m [43m    [49m[43m)[49m
[1;32m    178[0m [38;5;28;01mexcept[39;00m SocketTimeout:

File [0;32m/usr/share/miniconda/lib/python3.9/site-packages/urllib3/util/connection.py:72[0m, in [0;36mcreate_connection[0;34m(address, timeout, source_address, socket_options)[0m
[1;32m     68[0m     [38;5;28;01mreturn[39;00m six[38;5;241m.[39mraise_from(
[1;32m     69[0m         LocationParseError([38;5;124mu[39m[38;5;124m"[39m[38;5;124m'[39m[38;5;132;01m%s[39;00m[38;5;124m'[39m[38;5;124m, label empty or too long[39m[38;5;124m"[39m [38;5;241m%[39m host), [38;5;28;01mNone[39;00m
[1;32m     70[0m     )
[0;32m---> 72[0m [38;5;28;01mfor[39;00m res [38;5;129;01min[39;00m [43msocket[49m[38;5;241;43m.[39;49m[43mgetaddrinfo[49m[43m([49m[43mhost[49m[43m,[49m[43m [49m[43mport[49m[43m,[49m[43m [49m[43mfamily[49m[43m,[49m[43m [49m[43msocket[49m[38;5;241;43m.[39;49m[43mSOCK_STREAM[49m[43m)[49m:
[1;32m     73[0m     af, socktype, proto, canonname, sa [38;5;241m=[39m res

File [0;32m/usr/share/miniconda/lib/python3.9/socket.py:954[0m, in [0;36mgetaddrinfo[0;34m(host, port, family, type, proto, flags)[0m
[1;32m    953[0m addrlist [38;5;241m=[39m []
[0;32m--> 954[0m [38;5;28;01mfor[39;00m res [38;5;129;01min[39;00m [43m_socket[49m[38;5;241;43m.[39;49m[43mgetaddrinfo[49m[43m([49m[43mhost[49m[43m,[49m[43m [49m[43mport[49m[43m,[49m[43m [49m[43mfamily[49m[43m,[49m[43m [49m[38;5;28;43mtype[39;49m[43m,[49m[43m [49m[43mproto[49m[43m,[49m[43m [49m[43mflags[49m[43m)[49m:
[1;32m    955[0m     af, socktype, proto, canonname, sa [38;5;241m=[39m res

[0;31mgaierror[0m: [Errno -5] No address associated with hostname

During handling of the above exception, another exception occurred:

[0;31mNewConnectionError[0m                        Traceback (most recent call last)
File [0;32m/usr/share/miniconda/lib/python3.9/site-packages/urllib3/connectionpool.py:703[0m, in [0;36mHTTPConnectionPool.urlopen[0;34m(self, method, url, body, headers, retries, redirect, assert_same_host, timeout, pool_timeout, release_conn, chunked, body_pos, **response_kw)[0m
[1;32m    702[0m [38;5;66;03m# Make the request on the httplib connection object.[39;00m
[0;32m--> 703[0m httplib_response [38;5;241m=[39m [38;5;28;43mself[39;49m[38;5;241;43m.[39;49m[43m_make_request[49m[43m([49m
[1;32m    704[0m [43m    [49m[43mconn[49m[43m,[49m
[1;32m    705[0m [43m    [49m[43mmethod[49m[43m,[49m
[1;32m    706[0m [43m    [49m[43murl[49m[43m,[49m
[1;32m    707[0m [43m    [49m[43mtimeout[49m[38;5;241;43m=[39;49m[43mtimeout_obj[49m[43m,[49m
[1;32m    708[0m [43m    [49m[43mbody[49m[38;5;241;43m=[39;49m[43mbody[49m[43m,[49m
[1;32m    709[0m [43m    [49m[43mheaders[49m[38;5;241;43m=[39;49m[43mheaders[49m[43m,[49m
[1;32m    710[0m [43m    [49m[43mchunked[49m[38;5;241;43m=[39;49m[43mchunked[49m[43m,[49m
[1;32m    711[0m [43m[49m[43m)[49m
[1;32m    713[0m [38;5;66;03m# If we're going to release the connection in ``finally:``, then[39;00m
[1;32m    714[0m [38;5;66;03m# the response doesn't need to know about the connection. Otherwise[39;00m
[1;32m    715[0m [38;5;66;03m# it will also try to release it and we'll have a double-release[39;00m
[1;32m    716[0m [38;5;66;03m# mess.[39;00m

File [0;32m/usr/share/miniconda/lib/python3.9/site-packages/urllib3/connectionpool.py:386[0m, in [0;36mHTTPConnectionPool._make_request[0;34m(self, conn, method, url, timeout, chunked, **httplib_request_kw)[0m
[1;32m    385[0m [38;5;28;01mtry[39;00m:
[0;32m--> 386[0m     [38;5;28;43mself[39;49m[38;5;241;43m.[39;49m[43m_validate_conn[49m[43m([49m[43mconn[49m[43m)[49m
[1;32m    387[0m [38;5;28;01mexcept[39;00m (SocketTimeout, BaseSSLError) [38;5;28;01mas[39;00m e:
[1;32m    388[0m     [38;5;66;03m# Py2 raises this as a BaseSSLError, Py3 raises it as socket timeout.[39;00m

File [0;32m/usr/share/miniconda/lib/python3.9/site-packages/urllib3/connectionpool.py:1040[0m, in [0;36mHTTPSConnectionPool._validate_conn[0;34m(self, conn)[0m
[1;32m   1039[0m [38;5;28;01mif[39;00m [38;5;129;01mnot[39;00m [38;5;28mgetattr[39m(conn, [38;5;124m"[39m[38;5;124msock[39m[38;5;124m"[39m, [38;5;28;01mNone[39;00m):  [38;5;66;03m# AppEngine might not have  `.sock`[39;00m
[0;32m-> 1040[0m     [43mconn[49m[38;5;241;43m.[39;49m[43mconnect[49m[43m([49m[43m)[49m
[1;32m   1042[0m [38;5;28;01mif[39;00m [38;5;129;01mnot[39;00m conn[38;5;241m.[39mis_verified:

File [0;32m/usr/share/miniconda/lib/python3.9/site-packages/urllib3/connection.py:358[0m, in [0;36mHTTPSConnection.connect[0;34m(self)[0m
[1;32m    356[0m [38;5;28;01mdef[39;00m [38;5;21mconnect[39m([38;5;28mself[39m):
[1;32m    357[0m     [38;5;66;03m# Add certificate verification[39;00m
[0;32m--> 358[0m     conn [38;5;241m=[39m [38;5;28;43mself[39;49m[38;5;241;43m.[39;49m[43m_new_conn[49m[43m([49m[43m)[49m
[1;32m    359[0m     hostname [38;5;241m=[39m [38;5;28mself[39m[38;5;241m.[39mhost

File [0;32m/usr/share/miniconda/lib/python3.9/site-packages/urllib3/connection.py:186[0m, in [0;36mHTTPConnection._new_conn[0;34m(self)[0m
[1;32m    185[0m [38;5;28;01mexcept[39;00m SocketError [38;5;28;01mas[39;00m e:
[0;32m--> 186[0m     [38;5;28;01mraise[39;00m NewConnectionError(
[1;32m    187[0m         [38;5;28mself[39m, [38;5;124m"[39m[38;5;124mFailed to establish a new connection: [39m[38;5;132;01m%s[39;00m[38;5;124m"[39m [38;5;241m%[39m e
[1;32m    188[0m     )
[1;32m    190[0m [38;5;28;01mreturn[39;00m conn

[0;31mNewConnectionError[0m: <urllib3.connection.HTTPSConnection object at 0x7f3ac84475e0>: Failed to establish a new connection: [Errno -5] No address associated with hostname

During handling of the above exception, another exception occurred:

[0;31mMaxRetryError[0m                             Traceback (most recent call last)
File [0;32m/usr/share/miniconda/lib/python3.9/site-packages/requests/adapters.py:440[0m, in [0;36mHTTPAdapter.send[0;34m(self, request, stream, timeout, verify, cert, proxies)[0m
[1;32m    439[0m [38;5;28;01mif[39;00m [38;5;129;01mnot[39;00m chunked:
[0;32m--> 440[0m     resp [38;5;241m=[39m [43mconn[49m[38;5;241;43m.[39;49m[43murlopen[49m[43m([49m
[1;32m    441[0m [43m        [49m[43mmethod[49m[38;5;241;43m=[39;49m[43mrequest[49m[38;5;241;43m.[39;49m[43mmethod[49m[43m,[49m
[1;32m    442[0m [43m        [49m[43murl[49m[38;5;241;43m=[39;49m[43murl[49m[43m,[49m
[1;32m    443[0m [43m        [49m[43mbody[49m[38;5;241;43m=[39;49m[43mrequest[49m[38;5;241;43m.[39;49m[43mbody[49m[43m,[49m
[1;32m    444[0m [43m        [49m[43mheaders[49m[38;5;241;43m=[39;49m[43mrequest[49m[38;5;241;43m.[39;49m[43mheaders[49m[43m,[49m
[1;32m    445[0m [43m        [49m[43mredirect[49m[38;5;241;43m=[39;49m[38;5;28;43;01mFalse[39;49;00m[43m,[49m
[1;32m    446[0m [43m        [49m[43massert_same_host[49m[38;5;241;43m=[39;49m[38;5;28;43;01mFalse[39;49;00m[43m,[49m
[1;32m    447[0m [43m        [49m[43mpreload_content[49m[38;5;241;43m=[39;49m[38;5;28;43;01mFalse[39;49;00m[43m,[49m
[1;32m    448[0m [43m        [49m[43mdecode_content[49m[38;5;241;43m=[39;49m[38;5;28;43;01mFalse[39;49;00m[43m,[49m
[1;32m    449[0m [43m        [49m[43mretries[49m[38;5;241;43m=[39;49m[38;5;28;43mself[39;49m[38;5;241;43m.[39;49m[43mmax_retries[49m[43m,[49m
[1;32m    450[0m [43m        [49m[43mtimeout[49m[38;5;241;43m=[39;49m[43mtimeout[49m
[1;32m    451[0m [43m    [49m[43m)[49m
[1;32m    453[0m [38;5;66;03m# Send the request.[39;00m
[1;32m    454[0m [38;5;28;01melse[39;00m:

File [0;32m/usr/share/miniconda/lib/python3.9/site-packages/urllib3/connectionpool.py:785[0m, in [0;36mHTTPConnectionPool.urlopen[0;34m(self, method, url, body, headers, retries, redirect, assert_same_host, timeout, pool_timeout, release_conn, chunked, body_pos, **response_kw)[0m
[1;32m    783[0m     e [38;5;241m=[39m ProtocolError([38;5;124m"[39m[38;5;124mConnection aborted.[39m[38;5;124m"[39m, e)
[0;32m--> 785[0m retries [38;5;241m=[39m [43mretries[49m[38;5;241;43m.[39;49m[43mincrement[49m[43m([49m
[1;32m    786[0m [43m    [49m[43mmethod[49m[43m,[49m[43m [49m[43murl[49m[43m,[49m[43m [49m[43merror[49m[38;5;241;43m=[39;49m[43me[49m[43m,[49m[43m [49m[43m_pool[49m[38;5;241;43m=[39;49m[38;5;28;43mself[39;49m[43m,[49m[43m [49m[43m_stacktrace[49m[38;5;241;43m=[39;49m[43msys[49m[38;5;241;43m.[39;49m[43mexc_info[49m[43m([49m[43m)[49m[43m[[49m[38;5;241;43m2[39;49m[43m][49m
[1;32m    787[0m [43m[49m[43m)[49m
[1;32m    788[0m retries[38;5;241m.[39msleep()

File [0;32m/usr/share/miniconda/lib/python3.9/site-packages/urllib3/util/retry.py:592[0m, in [0;36mRetry.increment[0;34m(self, method, url, response, error, _pool, _stacktrace)[0m
[1;32m    591[0m [38;5;28;01mif[39;00m new_retry[38;5;241m.[39mis_exhausted():
[0;32m--> 592[0m     [38;5;28;01mraise[39;00m MaxRetryError(_pool, url, error [38;5;129;01mor[39;00m ResponseError(cause))
[1;32m    594[0m log[38;5;241m.[39mdebug([38;5;124m"[39m[38;5;124mIncremented Retry for (url=[39m[38;5;124m'[39m[38;5;132;01m%s[39;00m[38;5;124m'[39m[38;5;124m): [39m[38;5;132;01m%r[39;00m[38;5;124m"[39m, url, new_retry)

[0;31mMaxRetryError[0m: HTTPSConnectionPool(host='bytesalad.stsci.edu', port=443): Max retries exceeded with url: /artifactory/ (Caused by NewConnectionError('<urllib3.connection.HTTPSConnection object at 0x7f3ac84475e0>: Failed to establish a new connection: [Errno -5] No address associated with hostname'))

During handling of the above exception, another exception occurred:

[0;31mConnectionError[0m                           Traceback (most recent call last)
Cell [0;32mIn [5], line 1[0m
[0;32m----> 1[0m input_file1 [38;5;241m=[39m [43mget_bigdata[49m[43m([49m[38;5;124;43m'[39;49m[38;5;124;43mjwst_validation_notebooks[39;49m[38;5;124;43m'[39;49m[43m,[49m
[1;32m      2[0m [43m                     [49m[38;5;124;43m'[39;49m[38;5;124;43mvalidation_data[39;49m[38;5;124;43m'[39;49m[43m,[49m
[1;32m      3[0m [43m                     [49m[38;5;124;43m'[39;49m[38;5;124;43moutlier_detection[39;49m[38;5;124;43m'[39;49m[43m,[49m
[1;32m      4[0m [43m                     [49m[38;5;124;43m'[39;49m[38;5;124;43moutlier_detection_miri_test[39;49m[38;5;124;43m'[39;49m[43m,[49m[43m [49m
[1;32m      5[0m [43m                     [49m[38;5;124;43m'[39;49m[38;5;124;43mdet_image_seq1_MIRIMAGE_F560Wexp1_cal.fits[39;49m[38;5;124;43m'[39;49m[43m)[49m
[1;32m      6[0m input_file2 [38;5;241m=[39m get_bigdata([38;5;124m'[39m[38;5;124mjwst_validation_notebooks[39m[38;5;124m'[39m,
[1;32m      7[0m                      [38;5;124m'[39m[38;5;124mvalidation_data[39m[38;5;124m'[39m,
[1;32m      8[0m                      [38;5;124m'[39m[38;5;124moutlier_detection[39m[38;5;124m'[39m,
[1;32m      9[0m                      [38;5;124m'[39m[38;5;124moutlier_detection_miri_test[39m[38;5;124m'[39m, 
[1;32m     10[0m                      [38;5;124m'[39m[38;5;124mdet_image_seq2_MIRIMAGE_F560Wexp1_cal.fits[39m[38;5;124m'[39m)
[1;32m     11[0m input_file3 [38;5;241m=[39m get_bigdata([38;5;124m'[39m[38;5;124mjwst_validation_notebooks[39m[38;5;124m'[39m,
[1;32m     12[0m                      [38;5;124m'[39m[38;5;124mvalidation_data[39m[38;5;124m'[39m,
[1;32m     13[0m                      [38;5;124m'[39m[38;5;124moutlier_detection[39m[38;5;124m'[39m,
[1;32m     14[0m                      [38;5;124m'[39m[38;5;124moutlier_detection_miri_test[39m[38;5;124m'[39m, 
[1;32m     15[0m                      [38;5;124m'[39m[38;5;124mdet_image_seq3_MIRIMAGE_F560Wexp1_cal.fits[39m[38;5;124m'[39m)

File [0;32m/usr/share/miniconda/lib/python3.9/site-packages/ci_watson/artifactory_helpers.py:200[0m, in [0;36mget_bigdata[0;34m(docopy, timeout, chunk_size, *args)[0m
[1;32m    164[0m [38;5;28;01mdef[39;00m [38;5;21mget_bigdata[39m([38;5;241m*[39margs, docopy[38;5;241m=[39m[38;5;28;01mTrue[39;00m, timeout[38;5;241m=[39mTIMEOUT, chunk_size[38;5;241m=[39mCHUNK_SIZE):
[1;32m    165[0m     [38;5;124;03m"""[39;00m
[1;32m    166[0m [38;5;124;03m    Acquire requested data from a managed resource[39;00m
[1;32m    167[0m [38;5;124;03m    to the current directory.[39;00m
[0;32m   (...)[0m
[1;32m    198[0m 
[1;32m    199[0m [38;5;124;03m    """[39;00m
[0;32m--> 200[0m     src [38;5;241m=[39m os[38;5;241m.[39mpath[38;5;241m.[39mjoin([43mget_bigdata_root[49m[43m([49m[43m)[49m, [38;5;241m*[39margs)
[1;32m    201[0m     src_exists [38;5;241m=[39m os[38;5;241m.[39mpath[38;5;241m.[39mexists(src)
[1;32m    202[0m     src_is_url [38;5;241m=[39m check_url(src)

File [0;32m/usr/share/miniconda/lib/python3.9/site-packages/ci_watson/artifactory_helpers.py:158[0m, in [0;36mget_bigdata_root[0;34m(envkey)[0m
[1;32m    153[0m     [38;5;28;01mraise[39;00m BigdataError(
[1;32m    154[0m         [38;5;124m'[39m[38;5;124mEnvironment variable [39m[38;5;132;01m{}[39;00m[38;5;124m is undefined[39m[38;5;124m'[39m[38;5;241m.[39mformat(envkey))
[1;32m    156[0m path [38;5;241m=[39m os[38;5;241m.[39menviron[envkey]
[0;32m--> 158[0m [38;5;28;01mif[39;00m os[38;5;241m.[39mpath[38;5;241m.[39mexists(path) [38;5;129;01mor[39;00m [43mcheck_url[49m[43m([49m[43mpath[49m[43m)[49m:
[1;32m    159[0m     [38;5;28;01mreturn[39;00m path
[1;32m    161[0m [38;5;28;01mreturn[39;00m [38;5;28;01mNone[39;00m

File [0;32m/usr/share/miniconda/lib/python3.9/site-packages/ci_watson/artifactory_helpers.py:102[0m, in [0;36mretry.<locals>.decorator.<locals>.wrapper[0;34m(*args, **kwargs)[0m
[1;32m    100[0m         retry [38;5;241m+[39m[38;5;241m=[39m [38;5;241m1[39m
[1;32m    101[0m         time[38;5;241m.[39msleep(delay)
[0;32m--> 102[0m [38;5;28;01mreturn[39;00m [43mfn[49m[43m([49m[38;5;241;43m*[39;49m[43margs[49m[43m,[49m[43m [49m[38;5;241;43m*[39;49m[38;5;241;43m*[39;49m[43mkwargs[49m[43m)[49m

File [0;32m/usr/share/miniconda/lib/python3.9/site-packages/ci_watson/artifactory_helpers.py:117[0m, in [0;36mcheck_url[0;34m(url, timeout)[0m
[1;32m    114[0m [38;5;28;01mimport[39;00m [38;5;21;01mrequests[39;00m
[1;32m    116[0m [38;5;66;03m# requests.head does not work with Artifactory landing page.[39;00m
[0;32m--> 117[0m r [38;5;241m=[39m [43mrequests[49m[38;5;241;43m.[39;49m[43mget[49m[43m([49m[43murl[49m[43m,[49m[43m [49m[43mallow_redirects[49m[38;5;241;43m=[39;49m[38;5;28;43;01mTrue[39;49;00m[43m,[49m[43m [49m[43mtimeout[49m[38;5;241;43m=[39;49m[43mtimeout[49m[43m)[49m
[1;32m    118[0m [38;5;66;03m# TODO: Can we simply return r.ok here?[39;00m
[1;32m    119[0m [38;5;28;01mif[39;00m r[38;5;241m.[39mstatus_code [38;5;241m>[39m[38;5;241m=[39m [38;5;241m400[39m:

File [0;32m/usr/share/miniconda/lib/python3.9/site-packages/requests/api.py:75[0m, in [0;36mget[0;34m(url, params, **kwargs)[0m
[1;32m     64[0m [38;5;28;01mdef[39;00m [38;5;21mget[39m(url, params[38;5;241m=[39m[38;5;28;01mNone[39;00m, [38;5;241m*[39m[38;5;241m*[39mkwargs):
[1;32m     65[0m     [38;5;124mr[39m[38;5;124;03m"""Sends a GET request.[39;00m
[1;32m     66[0m 
[1;32m     67[0m [38;5;124;03m    :param url: URL for the new :class:`Request` object.[39;00m
[0;32m   (...)[0m
[1;32m     72[0m [38;5;124;03m    :rtype: requests.Response[39;00m
[1;32m     73[0m [38;5;124;03m    """[39;00m
[0;32m---> 75[0m     [38;5;28;01mreturn[39;00m [43mrequest[49m[43m([49m[38;5;124;43m'[39;49m[38;5;124;43mget[39;49m[38;5;124;43m'[39;49m[43m,[49m[43m [49m[43murl[49m[43m,[49m[43m [49m[43mparams[49m[38;5;241;43m=[39;49m[43mparams[49m[43m,[49m[43m [49m[38;5;241;43m*[39;49m[38;5;241;43m*[39;49m[43mkwargs[49m[43m)[49m

File [0;32m/usr/share/miniconda/lib/python3.9/site-packages/requests/api.py:61[0m, in [0;36mrequest[0;34m(method, url, **kwargs)[0m
[1;32m     57[0m [38;5;66;03m# By using the 'with' statement we are sure the session is closed, thus we[39;00m
[1;32m     58[0m [38;5;66;03m# avoid leaving sockets open which can trigger a ResourceWarning in some[39;00m
[1;32m     59[0m [38;5;66;03m# cases, and look like a memory leak in others.[39;00m
[1;32m     60[0m [38;5;28;01mwith[39;00m sessions[38;5;241m.[39mSession() [38;5;28;01mas[39;00m session:
[0;32m---> 61[0m     [38;5;28;01mreturn[39;00m [43msession[49m[38;5;241;43m.[39;49m[43mrequest[49m[43m([49m[43mmethod[49m[38;5;241;43m=[39;49m[43mmethod[49m[43m,[49m[43m [49m[43murl[49m[38;5;241;43m=[39;49m[43murl[49m[43m,[49m[43m [49m[38;5;241;43m*[39;49m[38;5;241;43m*[39;49m[43mkwargs[49m[43m)[49m

File [0;32m/usr/share/miniconda/lib/python3.9/site-packages/requests/sessions.py:529[0m, in [0;36mSession.request[0;34m(self, method, url, params, data, headers, cookies, files, auth, timeout, allow_redirects, proxies, hooks, stream, verify, cert, json)[0m
[1;32m    524[0m send_kwargs [38;5;241m=[39m {
[1;32m    525[0m     [38;5;124m'[39m[38;5;124mtimeout[39m[38;5;124m'[39m: timeout,
[1;32m    526[0m     [38;5;124m'[39m[38;5;124mallow_redirects[39m[38;5;124m'[39m: allow_redirects,
[1;32m    527[0m }
[1;32m    528[0m send_kwargs[38;5;241m.[39mupdate(settings)
[0;32m--> 529[0m resp [38;5;241m=[39m [38;5;28;43mself[39;49m[38;5;241;43m.[39;49m[43msend[49m[43m([49m[43mprep[49m[43m,[49m[43m [49m[38;5;241;43m*[39;49m[38;5;241;43m*[39;49m[43msend_kwargs[49m[43m)[49m
[1;32m    531[0m [38;5;28;01mreturn[39;00m resp

File [0;32m/usr/share/miniconda/lib/python3.9/site-packages/requests/sessions.py:645[0m, in [0;36mSession.send[0;34m(self, request, **kwargs)[0m
[1;32m    642[0m start [38;5;241m=[39m preferred_clock()
[1;32m    644[0m [38;5;66;03m# Send the request[39;00m
[0;32m--> 645[0m r [38;5;241m=[39m [43madapter[49m[38;5;241;43m.[39;49m[43msend[49m[43m([49m[43mrequest[49m[43m,[49m[43m [49m[38;5;241;43m*[39;49m[38;5;241;43m*[39;49m[43mkwargs[49m[43m)[49m
[1;32m    647[0m [38;5;66;03m# Total elapsed time of the request (approximately)[39;00m
[1;32m    648[0m elapsed [38;5;241m=[39m preferred_clock() [38;5;241m-[39m start

File [0;32m/usr/share/miniconda/lib/python3.9/site-packages/requests/adapters.py:519[0m, in [0;36mHTTPAdapter.send[0;34m(self, request, stream, timeout, verify, cert, proxies)[0m
[1;32m    515[0m     [38;5;28;01mif[39;00m [38;5;28misinstance[39m(e[38;5;241m.[39mreason, _SSLError):
[1;32m    516[0m         [38;5;66;03m# This branch is for urllib3 v1.22 and later.[39;00m
[1;32m    517[0m         [38;5;28;01mraise[39;00m SSLError(e, request[38;5;241m=[39mrequest)
[0;32m--> 519[0m     [38;5;28;01mraise[39;00m [38;5;167;01mConnectionError[39;00m(e, request[38;5;241m=[39mrequest)
[1;32m    521[0m [38;5;28;01mexcept[39;00m ClosedPoolError [38;5;28;01mas[39;00m e:
[1;32m    522[0m     [38;5;28;01mraise[39;00m [38;5;167;01mConnectionError[39;00m(e, request[38;5;241m=[39mrequest)

[0;31mConnectionError[0m: HTTPSConnectionPool(host='bytesalad.stsci.edu', port=443): Max retries exceeded with url: /artifactory/ (Caused by NewConnectionError('<urllib3.connection.HTTPSConnection object at 0x7f3ac84475e0>: Failed to establish a new connection: [Errno -5] No address associated with hostname'))
ConnectionError: HTTPSConnectionPool(host='bytesalad.stsci.edu', port=443): Max retries exceeded with url: /artifactory/ (Caused by NewConnectionError('<urllib3.connection.HTTPSConnection object at 0x7f3ac84475e0>: Failed to establish a new connection: [Errno -5] No address associated with hostname'))

